Workbook

Sheet 📋 Instructions
B1: EFL — Executive Scorecard
B3: PURPOSE | C3: This workbook collects all raw data needed to calculate the 8 scorecard metrics and automatically computes status (Green/Yellow/Red).
B4: HOW TO USE | C4: 1. Each month/sprint: open the relevant DATA INPUT sheet and enter blue-text cells only.
C5: 2. The SCORECARD sheet pulls all computed metrics automatically — do not edit it.
C6: 3. The Formulas sheet is a reference for all metric definitions and thresholds.
B7: COLOR CODING | C7: Blue = Input cells (you fill these) | Black = Formula (auto-calculated) | Green = Cross-sheet link
B9: SHEETS
B10: 💵 Financial | C10: Enter monthly cost actuals, planned spend, story points, and EAC updates.
B11: 🏃 Sprints | C11: AUTO-CALCULATED - Pull all data from 'Team Sprints Input' sheet and 'Team Median Input'
B12: 🏃 Team Sprints Input | C12: Enterp per-sprint commitment and completion counts for each delivery teams.
B13: Team Median Input | C13: Enterp per-sprint median cycle time (Dev, QA and Overall) for each delivery teams.
B14: 🐛 Quality | C14: Enter defect counts by severity per release; enter rework effort and first time pass rate
B15: 📊 Scorecard | C15: AUTO-CALCULATED. All 7 metrics with RAG status and 3-month/3-sprint trend.
B16: 📐 Formulas | C16: Reference sheet with all metric definitions and threshold rules.
B18: FREQUENCY | C18: Financial & Quality = Monthly. Sprint metrics = Per sprint + monthly rollup.
B19: BASELINE | C19: Set baselines in the yellow-highlighted cells on the Financial and Sprint sheets on first use.

Sheet 📊 Scorecard
A1: EXECUTIVE SCORECARD — Auto-Calculated Summary
A2: All values pull automatically from the data input sheets. Do not edit this sheet.
A4: Metric | B4: Jan | C4: Feb | D4: Mar | E4: Apr | F4: May | G4: Jun | H4: Threshold / Target
A5: 💰 FINANCIAL HEALTH
A6: EAC vs SOW Budget % | B6: ='💵 Financial'!B8 -> 0.88415506 | C6: ='💵 Financial'!C8 -> 0.91358829 | D6: ='💵 Financial'!D8 -> 0.80146837 | E6: ='💵 Financial'!E8 -> 0.82033534 | F6: ='💵 Financial'!F8 -> 0.75294014 | G6: ='💵 Financial'!G8 -> 0.93200612 | H6: 🟢 ≤100% 🟡 100–105% 🔴 >105%
A7: EAC Status | B7: ='💵 Financial'!B9 -> 🟢 Green | C7: ='💵 Financial'!C9 -> 🟢 Green | D7: ='💵 Financial'!D9 -> 🟢 Green | E7: ='💵 Financial'!E9 -> 🟢 Green | F7: ='💵 Financial'!F9 -> 🟢 Green | G7: ='💵 Financial'!G9 -> 🟢 Green | H7: Auto from Financial sheet
A9: Monthly Burn Variance % | B9: ='💵 Financial'!B16 -> -0.047594877 | C9: =AVERAGE('💵 Financial'!C16,'💵 Financial'!D16) -> -0.040488615 | D9: =AVERAGE('💵 Financial'!E16,'💵 Financial'!G16) -> -0.12745968 | E9: =AVERAGE('💵 Financial'!H16,'💵 Financial'!I16) -> -0.096597042 | F9: =AVERAGE('💵 Financial'!H16,'💵 Financial'!J16) -> -0.12138979 | G9: =AVERAGE('💵 Financial'!I16,'💵 Financial'!K16) -> -0.32306728 | H9: 🟢 ≤±5% 🟡 ±5–10% 🔴 >±10%
A10: Burn Variance Status | B10: ='💵 Financial'!B17 -> 🟢 Green | C10: =IF(C9="","",IF(ABS(C9)<=0.05,"🟢 Green",IF(ABS(C9)<=0.1,"🟡 Yellow","🔴 Red"))) -> 🟢 Green | D10: =IF(D9="","",IF(ABS(D9)<=0.05,"🟢 Green",IF(ABS(D9)<=0.1,"🟡 Yellow","🔴 Red"))) -> 🔴 Red | E10: =IF(E9="","",IF(ABS(E9)<=0.05,"🟢 Green",IF(ABS(E9)<=0.1,"🟡 Yellow","🔴 Red"))) -> 🟡 Yellow | F10: =IF(F9="","",IF(ABS(F9)<=0.05,"🟢 Green",IF(ABS(F9)<=0.1,"🟡 Yellow","🔴 Red"))) -> 🔴 Red | G10: =IF(G9="","",IF(ABS(G9)<=0.05,"🟢 Green",IF(ABS(G9)<=0.1,"🟡 Yellow","🔴 Red"))) -> 🔴 Red | H10: Auto from Financial sheet
A12: Cost per SP — Stories Delivered($) | B12: ='💵 Financial'!B43 -> 2281.4432 | C12: ='💵 Financial'!B44 -> 979.39367 | D12: ='💵 Financial'!B45 -> 880.60686 | E12: ='💵 Financial'!B46 -> 835.65969 | F12: ='💵 Financial'!B47 -> 593.01262 | G12: ='💵 Financial'!B48 -> 526.12919 | H12: 🟢 Stable/↓ 🟡 ↑5–10% 🔴 ↑>10%
A13: Cost/SP Status | B13: NIL | C13: ='💵 Financial'!E44 -> 🟢 Green | D13: ='💵 Financial'!E45 -> 🟢 Green | E13: ='💵 Financial'!E46 -> 🟢 Green | F13: ='💵 Financial'!E47 -> 🟢 Green | G13: ='💵 Financial'!E48 -> 🟢 Green | H13: Auto from Financial sheet
A14: 3-Mo Rolling Avg Cost/SP ($) | B14: ='💵 Financial'!B29 -> NIL | C14: ='💵 Financial'!D29 -> 979.39367 | D14: ='💵 Financial'!G29 -> 920.12159 | E14: ='💵 Financial'!H29 -> 892.33755 | F14: ='💵 Financial'!J29 -> 872.43325 | G14: ='💵 Financial'!L29 -> 794.82528 | H14: Trend indicator
A16: 🏃 DELIVERY PREDICTABILITY & FLOW
A17: Commitment Reliability — Monthly Avg | B17: ='🏃 Sprints'!C21 -> 1 | C17: ='🏃 Sprints'!C22 -> 0.97943038 | D17: ='🏃 Sprints'!C23 -> 1.0559072 | E17: ='🏃 Sprints'!C24 -> 0.86234177 | F17: ='🏃 Sprints'!C25 -> 0.42052176 | G17: ='🏃 Sprints'!I21 -> 0.47904476 | H17: 🟢 ≥85% 🟡 75–84% 🔴 <75%
A18: CR Status | B18: ='🏃 Sprints'!D21 -> 🟢 Green | C18: ='🏃 Sprints'!D22 -> 🟢 Green | D18: ='🏃 Sprints'!D23 -> 🟢 Green | E18: ='🏃 Sprints'!D24 -> 🟢 Green | F18: ='🏃 Sprints'!D25 -> 🔴 Red | G18: ='🏃 Sprints'!J21 -> 🔴 Red | H18: Auto from Sprints sheet
A20: Cycle Time Median | B20: ='🏃 Sprints'!C30 -> 5.3 | C20: =AVERAGE('🏃 Sprints'!C31,'🏃 Sprints'!C32) -> 4.52875 | D20: =AVERAGE('🏃 Sprints'!C33,'🏃 Sprints'!C35) -> 5.1825 | E20: =AVERAGE('🏃 Sprints'!C36,'🏃 Sprints'!C37) -> 4.5175 | F20: =AVERAGE('🏃 Sprints'!C38,'🏃 Sprints'!C39) -> 4.7345833 | G20: =AVERAGE('🏃 Sprints'!C40,'🏃 Sprints'!C41) -> 7.62 | H20: 🟢 Stable/↓ 🟡 ↑ up to 10% 🔴 ↑>10%
A21: Cycle Time Status | B21: ='🏃 Sprints'!G30 -> 🟢 Green | C21: =IF(AVERAGE('🏃 Sprints'!F31,'🏃 Sprints'!F32)<=0, "🟢 Green", IF(AVERAGE('🏃 Sprints'!F31,'🏃 Sprints'!F32)<=10%, "🟢 Yellow", "🔴 Red")) -> 🟢 Green | D21: =IF(AVERAGE('🏃 Sprints'!F33,'🏃 Sprints'!F35)<=0, "🟢 Green", IF(AVERAGE('🏃 Sprints'!F33,'🏃 Sprints'!F35)<=10%, "🟢 Yellow", "🔴 Red")) -> 🟢 Green | E21: =IF(AVERAGE('🏃 Sprints'!F36,'🏃 Sprints'!F37)<=0, "🟢 Green", IF(AVERAGE('🏃 Sprints'!F36,'🏃 Sprints'!F37)<=10%, "🟢 Yellow", "🔴 Red")) -> 🟢 Green | F21: =IF(AVERAGE('🏃 Sprints'!F38,'🏃 Sprints'!F39)<=0, "🟢 Green", IF(AVERAGE('🏃 Sprints'!F38,'🏃 Sprints'!F39)<=10%, "🟢 Yellow", "🔴 Red")) -> 🟢 Green | G21: =IF(AVERAGE('🏃 Sprints'!F40,'🏃 Sprints'!F41)<=0, "🟢 Green", IF(AVERAGE('🏃 Sprints'!F40,'🏃 Sprints'!F41)<=10%, "🟢 Yellow", "🔴 Red")) -> 🔴 Red | H21: Auto from Sprints sheet
A23: 🐛 QUALITY & REWORK
A24: Defect Leakage % — Monthly | D24: ='🐛 Quality'!D20 -> 0.17647059 | E24: ='🐛 Quality'!D21 -> 0.015228426 | F24: ='🐛 Quality'!D22 -> 0.025862069 | G24: ='🐛 Quality'!D23 -> 0.090909091 | H24: 🟢 ≤10% 🟡 11–15% 🔴 >15%
A25: Leakage Status | D25: ='🐛 Quality'!E20 -> 🔴 Red | E25: ='🐛 Quality'!E21 -> 🟢 Green | F25: ='🐛 Quality'!E22 -> 🟢 Green | G25: ='🐛 Quality'!E23 -> 🟢 Green | H25: Auto from Quality sheet
A27: Rework Ratio — Monthly | B27: ='🐛 Quality'!E28 -> 0.034482759 | C27: =AVERAGE('🐛 Quality'!E29:E30) -> 0.21649781 | D27: =AVERAGE('🐛 Quality'!E31:E33) -> 0.21502271 | E27: =AVERAGE('🐛 Quality'!E34:E35) -> 0.2745463 | F27: =AVERAGE('🐛 Quality'!E36:E37) -> 0.27676394 | G27: =AVERAGE('🐛 Quality'!E38:E39) -> 0.34473092 | H27: Auto from Quality sheet
A28: Rework Status | B28: =IF(B27="","",IF(B27<=0.2,"🟢 Green",IF(B27<=0.3,"🟡 Yellow","🔴 Red"))) -> 🟢 Green | C28: =IF(C27="","",IF(C27<=0.2,"🟢 Green",IF(C27<=0.3,"🟡 Yellow","🔴 Red"))) -> 🟡 Yellow | D28: =IF(D27="","",IF(D27<=0.2,"🟢 Green",IF(D27<=0.3,"🟡 Yellow","🔴 Red"))) -> 🟡 Yellow | E28: =IF(E27="","",IF(E27<=0.2,"🟢 Green",IF(E27<=0.3,"🟡 Yellow","🔴 Red"))) -> 🟡 Yellow | F28: =IF(F27="","",IF(F27<=0.2,"🟢 Green",IF(F27<=0.3,"🟡 Yellow","🔴 Red"))) -> 🟡 Yellow | G28: =IF(G27="","",IF(G27<=0.2,"🟢 Green",IF(G27<=0.3,"🟡 Yellow","🔴 Red"))) -> 🔴 Red | H28: 🟢 ≤20% 🟡 21–30% 🔴 >30%
A30: First Time Pass Rate | D30: =AVERAGE('🐛 Quality'!E51:E52) -> 0.86363636 | E30: =AVERAGE('🐛 Quality'!E53:E54) -> 0.82600437 | F30: =AVERAGE('🐛 Quality'!E55:E56) -> 0.82620663 | G30: =AVERAGE('🐛 Quality'!E57:E58) -> 0.82205882
A31: Status | D31: =IF(D30="","",IF(D30>=95%,"🟢 Green",IF(D30>85%,"🟡 Yellow","🔴 Red"))) -> 🟡 Yellow | E31: =IF(E30="","",IF(E30>=95%,"🟢 Green",IF(E30>85%,"🟡 Yellow","🔴 Red"))) -> 🔴 Red | F31: =IF(F30="","",IF(F30>=95%,"🟢 Green",IF(F30>85%,"🟡 Yellow","🔴 Red"))) -> 🔴 Red | G31: =IF(G30="","",IF(G30>=95%,"🟢 Green",IF(G30>85%,"🟡 Yellow","🔴 Red"))) -> 🔴 Red | H31: >=95% : Green, >85% : Yellow, <=85% Red
A33: 📋 CURRENT MONTH SNAPSHOT — All Metrics at a Glance
A34: Metric | B34: Current Value | C34: Target | D34: Status | E34: Remarks
A35: EAC vs Budget | B35: =G6 -> 0.93200612 | C35: ≤100% | D35: =F7 -> 🟢 Green | E35: this is for June month
A36: Monthly Burn Variance | B36: =G9 -> -0.32306728 | C36: ±5% | D36: =G10 -> 🔴 Red | E36: 3 Onsite positions removed (Lalitha, Anil, Nanda) and rest all PTOs
A37: Cost/SP — Team | B37: =G12 -> 526.12919 | C37: 983 | D37: =G13 -> 🟢 Green
A38: Commitment Reliability | B38: =G17 -> 0.47904476 | C38: ≥85% | D38: =G18 -> 🔴 Red | E38: Overall red combining Q2 SP3, SP4 but SP2 commitment
A39: Cycle Time (Median) | B39: =G20 -> 7.62 | C39: 5.4 days | D39: =G21 -> 🔴 Red
A40: Prod Defect Leakage | B40: =G24 -> 0.090909091 | C40: ≤10% | D40: =G25 -> 🟢 Green
A41: Rework Ratio | B41: =G27 -> 0.34473092 | C41: ≤20% | D41: =G28 -> 🔴 Red | E41: this covers Q2 SP5 and Q2 SP6. Team 1 rework ratio was high 50%
A42: FTPR | B42: =G30 -> 0.82205882 | C42: >=95% | D42: =G31 -> 🔴 Red | E42: Team 1 and Team 2 had low FTPR consistently for both sprints

Sheet 💵 Financial
A1: FINANCIAL DATA INPUT — Monthly
A2: Blue cells = enter data. Black cells = auto-calculated. Update monthly.
A4: SECTION A — Budget & EAC
A5: Field | B5: Jan | C5: Feb | D5: Mar | E5: Apr | F5: May | G5: Jun | H5: July | J5: Notes
A6: SOW Budget Target ($) | B6: 471406 | C6: 471406 | D6: 471406 | E6: 471406 | F6: 471406 | G6: 399308 | J6: Enter SOW contract value
A7: Estimate at Completion EAC ($) | B7: 416796 | C7: 430671 | D7: 377817 | E7: 386711 | F7: 354940.5 | G7: 372157.5 | J7: Enter latest EAC each month
A8: EAC vs Budget % | B8: =B7/B6 -> 0.88415506 | C8: =C7/C6 -> 0.91358829 | D8: =D7/D6 -> 0.80146837 | E8: =E7/E6 -> 0.82033534 | F8: =IFERROR(F7/F6,"") -> 0.75294014 | G8: =IFERROR(G7/G6,"") -> 0.93200612 | J8: Auto: EAC÷Budget
A9: EAC Status | B9: =IF(B8="","",IF(B8<=1,"🟢 Green",IF(B8<=1.05,"🟡 Yellow","🔴 Red"))) -> 🟢 Green | C9: =IF(C8="","",IF(C8<=1,"🟢 Green",IF(C8<=1.05,"🟡 Yellow","🔴 Red"))) -> 🟢 Green | D9: =IF(D8="","",IF(D8<=1,"🟢 Green",IF(D8<=1.05,"🟡 Yellow","🔴 Red"))) -> 🟢 Green | E9: =IF(E8="","",IF(E8<=1,"🟢 Green",IF(E8<=1.05,"🟡 Yellow","🔴 Red"))) -> 🟢 Green | F9: =IF(F8="","",IF(F8<=1,"🟢 Green",IF(F8<=1.05,"🟡 Yellow","🔴 Red"))) -> 🟢 Green | G9: =IF(G8="","",IF(G8<=1,"🟢 Green",IF(G8<=1.05,"🟡 Yellow","🔴 Red"))) -> 🟢 Green | J9: Auto: RAG threshold ≤100%/≤105%/>105%
A11: SECTION B — Sprint Burn Variance (Exclude VM DM cost and Innova/ERIE cost)
A12: Field | B12: SP1 | C12: SP2 | D12: SP3 | E12: SP4 | F12: SP5 | G12: SP6 | H12: Q2 SP1 | I12: Q2 SP2 | J12: Q2 SP3 | K12: Q2 SP4 | L12: Q2 SP5 | M12: Q2 SP6 | N12: Notes
A13: Planned Monthly Spend ($) | B13: 210800 | C13: 210800 | D13: 210800 | E13: 210800 | F13: 210800 | G13: 210800 | H13: 210800 | I13: 192960 | J13: 190960 | K13: 190960 | L13: 190560 | M13: 190560 | N13: Enter planned budget for given sprint | Q13: ERIE | R13: Colton, John, Luke, Jacob, Marc, Jen, Erin, Matt, Sierra, Ryan, Mru
A14: Actual Monthly Spend ($) | B14: 200767 | C14: 195257 | D14: 209273 | E14: 198914 | F14: 182912 | G14: 168949 | H14: 182327 | I14: 181744.6 | J14: 170392 | K14: 78673.3 | L14: 156786.5 | M14: 167721.6 | N14: Enter actual spend | Q14: Innova | R14: 4 onsite (2 Mendix + 1 Integration + 1 BA), 4 offshore (2 Mendix + 2 QA)
A15: Burn Variance ($) | B15: =IF(B14="","",B14-B13) -> -10033 | C15: =IF(C14="","",C14-C13) -> -15543 | D15: =IF(D14="","",D14-D13) -> -1527 | E15: =IF(E14="","",E14-E13) -> -11886 | F15: =IF(F14="","",F14-F13) -> -27888 | G15: =IF(G14="","",G14-G13) -> -41851 | H15: =IF(H14="","",H14-H13) -> -28473 | I15: =IF(I14="","",I14-I13) -> -11215.4 | ... M15: =IF(M14="","",M14-M13) -> -22838.4 | N15: Auto: Actual−Planned
A16: Burn Variance % | B16: =IFERROR(IF(B15="","",B15/B13),"") -> -0.047594877 | C16: =IFERROR(IF(C15="","",C15/C13),"") -> -0.073733397 | D16: =IFERROR(IF(D15="","",D15/D13),"") -> -0.007243833 | E16: =IFERROR(IF(E15="","",E15/E13),"") -> -0.056385199 | F16: =IFERROR(IF(F15="","",F15/F13),"") -> -0.13229602 | G16: =IFERROR(IF(G15="","",G15/G13),"") -> -0.19853416 | H16: =IFERROR(IF(H15="","",H15/H13),"") -> -0.13507116 | I16: =IFERROR(IF(I15="","",I15/I13),"") -> -0.058122927 | ... M16: =IFERROR(IF(M15="","",M15/M13),"") -> -0.11984887 | N16: Auto: Variance÷Planned
A17: Burn Status | B17: =IF(B16="","",IF(ABS(B16)<=0.05,"🟢 Green",IF(ABS(B16)<=0.1,"🟡 Yellow","🔴 Red"))) -> 🟢 Green | C17: =IF(C16="","",IF(ABS(C16)<=0.05,"🟢 Green",IF(ABS(C16)<=0.1,"🟡 Yellow","🔴 Red"))) -> 🟡 Yellow | D17: =IF(D16="","",IF(ABS(D16)<=0.05,"🟢 Green",IF(ABS(D16)<=0.1,"🟡 Yellow","🔴 Red"))) -> 🟢 Green | E17: =IF(E16="","",IF(ABS(E16)<=0.05,"🟢 Green",IF(ABS(E16)<=0.1,"🟡 Yellow","🔴 Red"))) -> 🟡 Yellow | F17: =IF(F16="","",IF(ABS(F16)<=0.05,"🟢 Green",IF(ABS(F16)<=0.1,"🟡 Yellow","🔴 Red"))) -> 🔴 Red | G17: =IF(G16="","",IF(ABS(G16)<=0.05,"🟢 Green",IF(ABS(G16)<=0.1,"🟡 Yellow","🔴 Red"))) -> 🔴 Red | H17: =IF(H16="","",IF(ABS(H16)<=0.05,"🟢 Green",IF(ABS(H16)<=0.1,"🟡 Yellow","🔴 Red"))) -> 🔴 Red | I17: =IF(I16="","",IF(ABS(I16)<=0.05,"🟢 Green",IF(ABS(I16)<=0.1,"🟡 Yellow","🔴 Red"))) -> 🟡 Yellow | ... M17: =IF(M16="","",IF(ABS(M16)<=0.05,"🟢 Green",IF(ABS(M16)<=0.1,"🟡 Yellow","🔴 Red"))) -> 🔴 Red | N17: Auto: RAG ≤±5% / ≤±10% / >±10%
A19: SECTION C — Cost per Story Point (Only VM)
A20: Field | B20: SP1 | C20: SP2 | D20: SP3 | E20: SP4 | F20: SP5 | G20: SP6 | H20: Q2 SP1 | I20: Q2 SP2 | J20: Q2 SP3 | K20: Q2 SP4 | L20: Q2 SP5 | M20: Q2 SP6 | N20: Notes
A21: Story Points Delivered (All 4 Teams) | B21: ='🏃 Sprints'!N5 -> 84 | C21: ='🏃 Sprints'!N6 -> 178 | D21: ='🏃 Sprints'!N7 -> 147 | E21: ='🏃 Sprints'!N8 -> 323 | F21: ='🏃 Sprints'!N9 -> 164 | G21: ='🏃 Sprints'!N10 -> 113 | H21: ='🏃 Sprints'!N11 -> 220 | I21: ='🏃 Sprints'!N12 -> 141 | J21: ='🏃 Sprints'!N13 -> 169 | K21: ='🏃 Sprints'!N14 -> 162 | L21: ='🏃 Sprints'!N15 -> 215 | M21: ='🏃 Sprints'!N16 -> 135 | N21: Feature+story SP completed
A22: Defect (bugs) SP Delivered (All 4 Teams) | B22: ='🏃 Sprints'!O5 -> 4 | C22: ='🏃 Sprints'!O6 -> 22 | D22: ='🏃 Sprints'!O7 -> 66 | E22: ='🏃 Sprints'!O8 -> 108 | F22: ='🏃 Sprints'!O9 -> 37 | G22: ='🏃 Sprints'!O10 -> 20 | H22: ='🏃 Sprints'!O11 -> 22 | I22: ='🏃 Sprints'!O12 -> 57 | J22: ='🏃 Sprints'!O13 -> 41 | K22: ='🏃 Sprints'!O14 -> 48 | L22: ='🏃 Sprints'!O15 -> 83 | M22: ='🏃 Sprints'!O16 -> 50 | N22: Defect SP completed this month
A23: Total SP (incl. Defects) | B23: =IF(B21="","",B21+B22) -> 88 | C23: =IF(C21="","",C21+C22) -> 200 | D23: =IF(D21="","",D21+D22) -> 213 | E23: =IF(E21="","",E21+E22) -> 431 | F23: =IF(F21="","",F21+F22) -> 201 | G23: =IF(G21="","",G21+G22) -> 133 | H23: =IF(H21="","",H21+H22) -> 242 | I23: =IF(I21="","",I21+I22) -> 198 | ... M23: =IF(M21="","",M21+M22) -> 185 | N23: Auto: sum
A24: Team Cost ($) (from Actual Burn) | B24: =B14 -> 200767 | C24: =C14 -> 195257 | D24: =D14 -> 209273 | E24: =E14 -> 198914 | F24: =F14 -> 182912 | G24: =G14 -> 168949 | H24: =H14 -> 182327 | I24: =I14 -> 181744.6 | ... M24: =M14 -> 167721.6 | N24: Auto: links from Actual Spend above
A25: Cost per SP — Stories Completed ($) | B25: =IFERROR(IF(B21="","",B24/B21),"") -> 2390.0833 | C25: =IFERROR(IF(C21="","",C24/C21),"") -> 1096.9494 | D25: =IFERROR(IF(D21="","",D24/D21),"") -> 1423.6259 | E25: =IFERROR(IF(E21="","",E24/E21),"") -> 615.83282 | F25: =IFERROR(IF(F21="","",F24/F21),"") -> 1115.3171 | G25: =IFERROR(IF(G21="","",G24/G21),"") -> 1495.1239 | H25: =IFERROR(IF(H21="","",H24/H21),"") -> 828.75909 | I25: =IFERROR(IF(I21="","",I24/I21),"") -> 1288.9688 | ... M25: =IFERROR(IF(M21="","",M24/M21),"") -> 1242.3822 | N25: Auto: Team Cost ÷ Stories SP
A26: Cost per SP — Stories + Standalone Defects ($) | B26: =IFERROR(IF(B23="","",B24/B23),"") -> 2281.4432 | C26: =IFERROR(IF(C23="","",C24/C23),"") -> 976.285 | D26: =IFERROR(IF(D23="","",D24/D23),"") -> 982.50235 | E26: =IFERROR(IF(E23="","",E24/E23),"") -> 461.5174 | F26: =IFERROR(IF(F23="","",F24/F23),"") -> 910.00995 | G26: =IFERROR(IF(G23="","",G24/G23),"") -> 1270.2932 | H26: =IFERROR(IF(H23="","",H24/H23),"") -> 753.41736 | I26: =IFERROR(IF(I23="","",I24/I23),"") -> 917.90202 | ... M26: =IFERROR(IF(M23="","",M24/M23),"") -> 906.60324 | N26: Auto: Team Cost ÷ Total SP
A27: Baseline Cost/SP — Team ($) | B27: NIL | C27: NIL | D27: 983 | E27: 983 | F27: 983 | G27: 983 | H27: 983 | I27: 983 | J27: 983 | K27: 983 | L27: 983 | M27: 983 | N27: 🟡 Set once based on 2-3 Sprints
A28: Team Cost/SP Status | B28: =IF(B25="","",IF(B25<=B27,"🟢 Green",IF(B25<=B27*1.1,"🟡 Yellow","🔴 Red"))) -> 🟢 Green | C28: =IF(C25="","",IF(C25<=C27,"🟢 Green",IF(C25<=C27*1.1,"🟡 Yellow","🔴 Red"))) -> 🟢 Green | D28: =IF(D26="","",IF(D26<=D27,"🟢 Green",IF(D26<=D27*1.1,"🟡 Yellow","🔴 Red"))) -> 🟢 Green | E28: =IF(E26="","",IF(E26<=E27,"🟢 Green",IF(E26<=E27*1.1,"🟡 Yellow","🔴 Red"))) -> 🟢 Green | F28: =IF(F26="","",IF(F26<=F27,"🟢 Green",IF(F26<=F27*1.1,"🟡 Yellow","🔴 Red"))) -> 🟢 Green | G28: =IF(G26="","",IF(G26<=G27,"🟢 Green",IF(G26<=G27*1.1,"🟡 Yellow","🔴 Red"))) -> 🔴 Red | H28: =IF(H25="","",IF(H25<=H27,"🟢 Green",IF(H25<=H27*1.1,"🟡 Yellow","🔴 Red"))) -> 🟢 Green | I28: =IF(I25="","",IF(I25<=I27,"🟢 Green",IF(I25<=I27*1.1,"🟡 Yellow","🔴 Red"))) -> 🔴 Red | J28: =IF(J25="","",IF(J25<=J27,"🟢 Green",IF(J25<=J27*1.1,"🟡 Yellow","🔴 Red"))) -> 🟡 Yellow | K28: =IF(K25="","",IF(K25<=K27,"🟢 Green",IF(K25<=K27*1.1,"🟡 Yellow","🔴 Red"))) -> 🟢 Green | L28: =IF(L25="","",IF(L25<=L27,"🟢 Green",IF(L25<=L27*1.1,"🟡 Yellow","🔴 Red"))) -> 🟢 Green | M28: =IF(M25="","",IF(M25<=M27,"🟢 Green",IF(M25<=M27*1.1,"🟡 Yellow","🔴 Red"))) -> 🔴 Red | N28: Auto: RAG vs baseline ±10% (Variance <=10% Yellow, >10% Red)
A29: 3-Month Rolling Avg Cost/SP — Team ($) | B29: NIL | C29: =IFERROR(AVERAGE(C26:C26),"") -> 976.285 | D29: =IFERROR(AVERAGE(C26:D26),"") -> 979.39367 | E29: =IFERROR(AVERAGE(C26:E26),"") -> 806.76825 | F29: =IFERROR(AVERAGE(C26:F26),"") -> 832.57867 | G29: =IFERROR(AVERAGE(C26:G26),"") -> 920.12159 | H29: =IFERROR(AVERAGE(C26:H26),"") -> 892.33755 | I29: =IFERROR(AVERAGE(C26:I26),"") -> 895.98962 | J29: =IFERROR(AVERAGE(D26:J26),"") -> 872.43325 | K29: =IFERROR(AVERAGE(E26:K26),"") -> 785.59503 | L29: =IFERROR(AVERAGE(F26:L26),"") -> 794.82528 | M29: =IFERROR(AVERAGE(G26:M26),"") -> 794.33861 | N29: Auto: rolling 3-month avg (for trend reporting)
A32: MONTHLY ROLLUP — Budget & EAC
A33: Month | B33: Budget | C33: Actual | D33: Variance ($) | E33: Variance % | F33: 3-Sprint Trend
A34: January | B34: =B6 -> 471406 | C34: =B7 -> 416796 | D34: =B34-C34 -> 54610 | E34: =C34/B34 -> 0.88415506 | F34: =IF(E34="","",IF(E34<=1,"🟢 Green",IF(E34<=1.05,"🟡 Yellow","🔴 Red"))) -> 🟢 Green
A35: February | B35: =B6+C6 -> 942812 | C35: =B7+C7 -> 847467 | D35: =B35-C35 -> 95345 | E35: =C35/B35 -> 0.89887167 | F35: =IF(E35="","",IF(E35<=1,"🟢 Green",IF(E35<=1.05,"🟡 Yellow","🔴 Red"))) -> 🟢 Green
A36: March | B36: =B35+D6 -> 1414218 | C36: =C35+D7 -> 1225284 | D36: =B36-C36 -> 188934 | E36: =C36/B36 -> 0.86640391 | F36: =IF(E36="","",IF(E36<=1,"🟢 Green",IF(E36<=1.05,"🟡 Yellow","🔴 Red"))) -> 🟢 Green
A37: April | B37: =B36+E6 -> 1885624 | C37: =C36+E7 -> 1611995 | D37: =B37-C37 -> 273629 | E37: =C37/B37 -> 0.85488676 | F37: =IF(E37="","",IF(E37<=1,"🟢 Green",IF(E37<=1.05,"🟡 Yellow","🔴 Red"))) -> 🟢 Green
A38: May | B38: =B37+F6 -> 2357030 | C38: =C37+F7 -> 1966935.5 | D38: =B38-C38 -> 390094.5 | E38: =C38/B38 -> 0.83449744 | F38: =IF(E38="","",IF(E38<=1,"🟢 Green",IF(E38<=1.05,"🟡 Yellow","🔴 Red"))) -> 🟢 Green
A39: June | B39: =B38+G6 -> 2756338 | C39: =C38+G7 -> 2339093 | D39: =B39-C39 -> 417245 | E39: =C39/B39 -> 0.84862343 | F39: =IF(E39="","",IF(E39<=1,"🟢 Green",IF(E39<=1.05,"🟡 Yellow","🔴 Red"))) -> 🟢 Green
A41: MONTHLY ROLLUP — Cost per Story Point
A42: Month | B42: Actual | C42: Baseline | D42: Variance % | E42: Trend
A43: January | B43: =B26 -> 2281.4432 | C43: =B27 -> NIL | D43: =(B43-C43)/C43 -> #VALUE! | E43: =IF(B43="","",IF(B43<=C43,"🟢 Green",IF(B43<=C43*1.1,"🟡 Yellow","🔴 Red"))) -> 🟢 Green
A44: February | B44: =AVERAGE(C26:D26) -> 979.39367 | C44: =D27 -> 983 | D44: =((B44-C44)/C44) -> -0.0036686941 | E44: =IF(B44="","",IF(B44<=C44,"🟢 Green",IF(B44<=C44*1.1,"🟡 Yellow","🔴 Red"))) -> 🟢 Green
A45: March | B45: =AVERAGE(E26:G26) -> 880.60686 | C45: =D27 -> 983 | D45: =((B45-C45)/C45) -> -0.10416393 | E45: =IF(B45="","",IF(B45<=C45,"🟢 Green",IF(B45<=C45*1.1,"🟡 Yellow","🔴 Red"))) -> 🟢 Green
A46: April | B46: =AVERAGE(H26:I26) -> 835.65969 | C46: =D27 -> 983 | D46: =((B46-C46)/C46) -> -0.14988842 | E46: =IF(B46="","",IF(B46<=C46,"🟢 Green",IF(B46<=C46*1.1,"🟡 Yellow","🔴 Red"))) -> 🟢 Green
...

Sheet 🐛 Quality
A1: QUALITY DATA INPUT — Monthly & Per Release
B2: Enter defect data per release. Enter effort hours monthly. Status is auto-calculated.
A4: SECTION A — Production Defect Leakage (Per Release) - 0–10% : Green 11–15% : Yellow, 15%> : Red
B5: Formula: Prod Defect / All Defects X 100 | Sev1=5× Sev2=3× Sev3=1×
A6: Release / Feature | B6: Month | C6: Prod Defects Sev 1 (#) | D6: Prod Defects Sev 2 (#) | E6: Prod Defects Sev 3 (#) | F6: Prod Defects Sev 4 (#) | G6: Prod Defects Sev 5 (#) | H6: Total Prod Defects | I6: QA Defects | J6: UAT Defects | K6: Total Defects | L6: Leakage % (auto) | M6: Leakage Status
A7: EEL STOLI Release | B7: March | C7: 0 | F7: 2 | G7: 1 | H7: =SUM(C7:G7) -> 3 | I7: 17 | J7: 0 | K7: =SUM(I7:J7) -> 17 | L7: =SUM(C7:G7)/K7 -> 0.17647059 | M7: =IF(L7="","",IF(L7<=0.1,"🟢 Green",IF(L7<=0.15,"🟡 Yellow","🔴 Red"))) -> 🔴 Red
A8: TUW Pilot | B8: April | D8: 1 | E8: 3 | F8: 5 | H8: =SUM(C8:G8) -> 9 | I8: 573 | J8: 18 | K8: =SUM(I8:J8) -> 591 | L8: =SUM(C8:G8)/K8 -> 0.015228426 | M8: =IF(L8="","",IF(L8<=0.1,"🟢 Green",IF(L8<=0.15,"🟡 Yellow","🔴 Red"))) -> 🟢 Green
A9: TUW 1.1 | B9: May | D9: 2 | E9: 1 | H9: =SUM(C9:G9) -> 3 | I9: 93 | J9: 23 | K9: =SUM(I9:J9) -> 116 | L9: =SUM(C9:G9)/K9 -> 0.025862069 | M9: =IF(L9="","",IF(L9<=0.1,"🟢 Green",IF(L9<=0.15,"🟡 Yellow","🔴 Red"))) -> 🟢 Green
A10: TUW 1.3 | B10: June | D10: 4 | E10: 14 | F10: 3 | H10: =SUM(C10:G10) -> 21 | I10: 229 | J10: 2 | K10: =SUM(I10:J10) -> 231 | L10: =IFERROR(IF(SUM(C10:J10)=0,"",(C10*5+D10*3+E10*1)/(C10*5+D10*3+E10*1+H10*5+I10*3+J10*1)),"") -> 0.031707317 | M10: =IF(L10="","",IF(L10<=0.1,"🟢 Green",IF(L10<=0.15,"🟡 Yellow","🔴 Red"))) -> 🟢 Green
L11: =IFERROR(IF(SUM(C11:J11)=0,"",(C11*5+D11*3+E11*1)/(C11*5+D11*3+E11*1+H11*5+I11*3+J11*1)),"") | M11: =IF(L11="","",IF(L11<=0.1,"🟢 Green",IF(L11<=0.15,"🟡 Yellow","🔴 Red")))
L12: =IFERROR(IF(SUM(C12:J12)=0,"",(C12*5+D12*3+E12*1)/(C12*5+D12*3+E12*1+H12*5+I12*3+J12*1)),"") | M12: =IF(L12="","",IF(L12<=0.1,"🟢 Green",IF(L12<=0.15,"🟡 Yellow","🔴 Red")))
L13: =IFERROR(IF(SUM(C13:J13)=0,"",(C13*5+D13*3+E13*1)/(C13*5+D13*3+E13*1+H13*5+I13*3+J13*1)),"") | M13: =IF(L13="","",IF(L13<=0.1,"🟢 Green",IF(L13<=0.15,"🟡 Yellow","🔴 Red")))
L14: =IFERROR(IF(SUM(C14:J14)=0,"",(C14*5+D14*3+E14*1)/(C14*5+D14*3+E14*1+H14*5+I14*3+J14*1)),"") | M14: =IF(L14="","",IF(L14<=0.1,"🟢 Green",IF(L14<=0.15,"🟡 Yellow","🔴 Red")))
L15: =IFERROR(IF(SUM(C15:J15)=0,"",(C15*5+D15*3+E15*1)/(C15*5+D15*3+E15*1+H15*5+I15*3+J15*1)),"") | M15: =IF(L15="","",IF(L15<=0.1,"🟢 Green",IF(L15<=0.15,"🟡 Yellow","🔴 Red")))
L16: =IFERROR(IF(SUM(C16:J16)=0,"",(C16*5+D16*3+E16*1)/(C16*5+D16*3+E16*1+H16*5+I16*3+J16*1)),"") | M16: =IF(L16="","",IF(L16<=0.1,"🟢 Green",IF(L16<=0.15,"🟡 Yellow","🔴 Red")))
A18: SECTION B — Monthly Defect Leakage Rollup - 0–10% : Green 11–15% : Yellow, 15%> : Red
A19: Month | B19: Total Prod Defects | C19: Total Pre-prod Defects | D19: Leakage % | E19: Status
A20: March | B20: =SUMPRODUCT((B7:B16=A20)*(H7:H16)) -> 3 | C20: =SUMPRODUCT((B7:B16=A20)*K7:K16) -> 17 | D20: =B20/C20 -> 0.17647059 | E20: =IF(D20="","",IF(D20<=0.1,"🟢 Green",IF(D20<=0.15,"🟡 Yellow","🔴 Red"))) -> 🔴 Red
A21: April | B21: =SUMPRODUCT((B8:B17=A21)*(H8:H17)) -> 9 | C21: =SUMPRODUCT((B8:B17=A21)*K8:K17) -> 591 | D21: =B21/C21 -> 0.015228426 | E21: =IF(D21="","",IF(D21<=0.1,"🟢 Green",IF(D21<=0.15,"🟡 Yellow","🔴 Red"))) -> 🟢 Green
A22: May | B22: =SUMPRODUCT((B9:B18=A22)*(H9:H18)) -> 3 | C22: =SUMPRODUCT((B9:B18=A22)*K9:K18) -> 116 | D22: =B22/C22 -> 0.025862069 | E22: =IF(D22="","",IF(D22<=0.1,"🟢 Green",IF(D22<=0.15,"🟡 Yellow","🔴 Red"))) -> 🟢 Green
A23: June | B23: =SUMPRODUCT((B10:B19=A23)*(H10:H19)) -> 21 | C23: =SUMPRODUCT((B10:B19=A23)*K10:K19) -> 231 | D23: =B23/C23 -> 0.090909091 | E23: =IF(D23="","",IF(D23<=0.1,"🟢 Green",IF(D23<=0.15,"🟡 Yellow","🔴 Red"))) -> 🟢 Green
A25: SECTION C — Rework Ratio (Sprint and Monthly View) - <=20% : Green, <=30% : Yellow, >30% Red
A26: Rework Ratio = Defect Effort in Points/ Total Completed Story Points × 100
A27: Sprint ID | B27: Month | C27: Rework # (Standalone Bugs) | D27: Total Completed | E27: Rework Ratio | F27: Status | G27: Notes | H27: Mitigation
A28: Sprint 1 | B28: January | C28: =IFERROR(SUMIFS('🏃 Sprints'!H:H,'🏃 Sprints'!A:A,$A28,'🏃 Sprints'!B:B,$B28),0) -> 4 | D28: =IFERROR(SUMIFS('🏃 Sprints'!J:J,'🏃 Sprints'!A:A,$A28,'🏃 Sprints'!B:B,$B28),0) -> 116 | E28: =C28/D28 -> 0.034482759 | F28: =IF(E28="","",IF(E28<=0.2,"🟢 Green",IF(E28<=0.3,"🟡 Yellow","🔴 Red"))) -> 🟢 Green
A29: Sprint 2 | B29: February | C29: =IFERROR(SUMIFS('🏃 Sprints'!H:H,'🏃 Sprints'!A:A,$A29,'🏃 Sprints'!B:B,$B29),0) -> 34 | D29: =IFERROR(SUMIFS('🏃 Sprints'!J:J,'🏃 Sprints'!A:A,$A29,'🏃 Sprints'!B:B,$B29),0) -> 404 | E29: =C29/D29 -> 0.084158416 | F29: =IF(E29="","",IF(E29<=0.2,"🟢 Green",IF(E29<=0.3,"🟡 Yellow","🔴 Red"))) -> 🟢 Green
A30: Sprint 3 | B30: February | C30: =IFERROR(SUMIFS('🏃 Sprints'!H:H,'🏃 Sprints'!A:A,$A30,'🏃 Sprints'!B:B,$B30),0) -> 75 | D30: =IFERROR(SUMIFS('🏃 Sprints'!J:J,'🏃 Sprints'!A:A,$A30,'🏃 Sprints'!B:B,$B30),0) -> 215 | E30: =C30/D30 -> 0.34883721 | F30: =IF(E30="","",IF(E30<=0.2,"🟢 Green",IF(E30<=0.3,"🟡 Yellow","🔴 Red"))) -> 🔴 Red
A31: Sprint 4 | B31: March | C31: =IFERROR(SUMIFS('🏃 Sprints'!H:H,'🏃 Sprints'!A:A,$A31,'🏃 Sprints'!B:B,$B31),0) -> 127 | D31: =IFERROR(SUMIFS('🏃 Sprints'!J:J,'🏃 Sprints'!A:A,$A31,'🏃 Sprints'!B:B,$B31),0) -> 439 | E31: =C31/D31 -> 0.28929385 | F31: =IF(E31="","",IF(E31<=0.2,"🟢 Green",IF(E31<=0.3,"🟡 Yellow","🔴 Red"))) -> 🟡 Yellow
A32: Sprint 5 | B32: March | C32: =IFERROR(SUMIFS('🏃 Sprints'!H:H,'🏃 Sprints'!A:A,$A32,'🏃 Sprints'!B:B,$B32),0) -> 60 | D32: =IFERROR(SUMIFS('🏃 Sprints'!J:J,'🏃 Sprints'!A:A,$A32,'🏃 Sprints'!B:B,$B32),0) -> 351 | E32: =C32/D32 -> 0.17094017 | F32: =IF(E32="","",IF(E32<=0.2,"🟢 Green",IF(E32<=0.3,"🟡 Yellow","🔴 Red"))) -> 🟢 Green
A33: Sprint 6 | B33: March | C33: =IFERROR(SUMIFS('🏃 Sprints'!H:H,'🏃 Sprints'!A:A,$A33,'🏃 Sprints'!B:B,$B33),0) -> 39 | D33: =IFERROR(SUMIFS('🏃 Sprints'!J:J,'🏃 Sprints'!A:A,$A33,'🏃 Sprints'!B:B,$B33),0) -> 211 | E33: =C33/D33 -> 0.18483412 | F33: =IF(E33="","",IF(E33<=0.2,"🟢 Green",IF(E33<=0.3,"🟡 Yellow","🔴 Red"))) -> 🟢 Green
A34: Q2 Sprint 1 | B34: April | C34: =IFERROR(SUMIFS('🏃 Sprints'!H:H,'🏃 Sprints'!A:A,$A34,'🏃 Sprints'!B:B,$B34),0) -> 37 | D34: =IFERROR(SUMIFS('🏃 Sprints'!J:J,'🏃 Sprints'!A:A,$A34,'🏃 Sprints'!B:B,$B34),0) -> 307 | E34: =C34/D34 -> 0.12052117 | F34: =IF(E34="","",IF(E34<=0.2,"🟢 Green",IF(E34<=0.3,"🟡 Yellow","🔴 Red"))) -> 🟢 Green
A35: Q2 Sprint 2 | B35: April | C35: =IFERROR(SUMIFS('🏃 Sprints'!H:H,'🏃 Sprints'!A:A,$A35,'🏃 Sprints'!B:B,$B35),0) -> 102 | D35: =IFERROR(SUMIFS('🏃 Sprints'!J:J,'🏃 Sprints'!A:A,$A35,'🏃 Sprints'!B:B,$B35),0) -> 238 | E35: =C35/D35 -> 0.42857143 | F35: =IF(E35="","",IF(E35<=0.2,"🟢 Green",IF(E35<=0.3,"🟡 Yellow","🔴 Red"))) -> 🔴 Red | G35: The rework % increase due to Team 1 uncovering App Packet and Policy Packet form related defects | H35: Coding/design errors - Solution lead of team 1 agreed to increase unit testing coverage
A36: Q2 Sprint 3 | B36: May | C36: =IFERROR(SUMIFS('🏃 Sprints'!H:H,'🏃 Sprints'!A:A,$A36,'🏃 Sprints'!B:B,$B36),0) -> 61 | D36: =IFERROR(SUMIFS('🏃 Sprints'!J:J,'🏃 Sprints'!A:A,$A36,'🏃 Sprints'!B:B,$B36),0) -> 300 | E36: =C36/D36 -> 0.20333333 | F36: =IF(E36="","",IF(E36<=0.2,"🟢 Green",IF(E36<=0.3,"🟡 Yellow","🔴 Red"))) -> 🟡 Yellow | G36: The rework % came down as more story points completed in this sprint
A37: Q2 Sprint 4 | B37: May | C37: =IFERROR(SUMIFS('🏃 Sprints'!H:H,'🏃 Sprints'!A:A,$A37,'🏃 Sprints'!B:B,$B37),0) -> 90 | D37: =IFERROR(SUMIFS('🏃 Sprints'!J:J,'🏃 Sprints'!A:A,$A37,'🏃 Sprints'!B:B,$B37),0) -> 257 | E37: =C37/D37 -> 0.35019455 | F37: =IF(E37="","",IF(E37<=0.2,"🟢 Green",IF(E37<=0.3,"🟡 Yellow","🔴 Red"))) -> 🔴 Red | G37: Team 1 primarily worked on Release 1.1 and 1.2 activities ( thus increasing the rework percentage) Team 2 also worked on more defects compared to previous sprint leading up to Final Expense Pilot release. Team 4 worked on more defects as well in this sprint.
A38: Q2 Sprint 5 | B38: June | C38: =IFERROR(SUMIFS('🏃 Sprints'!H:H,'🏃 Sprints'!A:A,$A38,'🏃 Sprints'!B:B,$B38),0) -> 104 | D38: =IFERROR(SUMIFS('🏃 Sprints'!J:J,'🏃 Sprints'!A:A,$A38,'🏃 Sprints'!B:B,$B38),0) -> 317 | E38: =C38/D38 -> 0.32807571 | F38: =IF(E38="","",IF(E38<=0.2,"🟢 Green",IF(E38<=0.3,"🟡 Yellow","🔴 Red"))) -> 🔴 Red | G38: Team 1 primarily worked on bugs as part of Release activities ( thus increasing the rework percentage) Team 2 also worked on more defects compared to previous sprint leading up to Final Expense Pilot release.
A39: Q2 Sprint 6 | B39: June | C39: =IFERROR(SUMIFS('🏃 Sprints'!H:H,'🏃 Sprints'!A:A,$A39,'🏃 Sprints'!B:B,$B39),0) -> 73 | D39: =IFERROR(SUMIFS('🏃 Sprints'!J:J,'🏃 Sprints'!A:A,$A39,'🏃 Sprints'!B:B,$B39),0) -> 202 | E39: =C39/D39 -> 0.36138614 | F39: =IF(E39="","",IF(E39<=0.2,"🟢 Green",IF(E39<=0.3,"🟡 Yellow","🔴 Red"))) -> 🔴 Red | G39: Team 1 primarily worked on bugs as part of Release activities ( thus increasing the rework percentage) Team 2 also worked on more defects compared to previous sprint leading up to Final Expense Pilot release.
E40: =IF(C40+D40=0,"",C40+D40) | F40: =IFERROR(IF(E40="","",E40/B40),"") | G40: =IF(F40="","",IF(F40<=0.2,"🟢 Green",IF(F40<=0.3,"🟡 Yellow","🔴 Red")))
A44: SECTION D — First Time Pass Rate- >=95% : Green, >85% : Yellow, <=85% Red
A45: First Time Pass Rate = Total Stories with defects/ Total Completed Story Points × 100
A46: Sprint ID | B46: Month | C46: Total Stories W/O defects | D46: Total Stories Delivered | E46: First Time Pass % | F46: Status | G46: Notes
...

Sheet 🏃 Sprints
A1: SPRINT DATA INPUT — Per Sprint
A2: 1. Commitment Reliability - Delivery Predictability, Overcommitment vs execution blockers 2. Cycle Time (Median) - How fast value is delivered and Team efficiency
A3: SECTION A — Commitment Reliability (<75% - Red; >=75 to <85% - Yellow; >=85% - Green)
A4: Sprint ID | B4: Month | C4: Stories Planned | D4: Stories Defects Planned | E4: Standalone Bugs Planned | F4: Stories Completed | G4: Story Defects Completed | H4: Standalone Bugs Completed | I4: Total Planned (Exclude Story defects) | J4: Total Completed (Exclude Story defects) | K4: Baseline Velocity | L4: Completion % | M4: CR Status | N4: VM Completed Stories | O4: VM Standalone Bugs Completed | P4: Notes
A5: Sprint 1 | B5: January | C5: =SUMIFS('Team Sprints Input'!F:F,'Team Sprints Input'!$A:$A,$A5) -> 250 | D5: =SUMIFS('Team Sprints Input'!G:G,'Team Sprints Input'!$A:$A,$A5) -> 24 | E5: =SUMIFS('Team Sprints Input'!H:H,'Team Sprints Input'!$A:$A,$A5) -> 10 | F5: =SUMIFS('Team Sprints Input'!I:I,'Team Sprints Input'!$A:$A,$A5) -> 112 | G5: =SUMIFS('Team Sprints Input'!J:J,'Team Sprints Input'!$A:$A,$A5) -> 8 | H5: =SUMIFS('Team Sprints Input'!K:K,'Team Sprints Input'!$A:$A,$A5) -> 4 | I5: =C5+E5 -> 260 | J5: =F5+H5 -> 116 | K5: =SUMIFS('Team Sprints Input'!N:N, 'Team Sprints Input'!A:A, A5, 'Team Sprints Input'!E:E, B5) -> 116 | L5: =IFERROR(J5/K5,"") -> 1 | M5: =IF(L5="","",IF(L5>=0.85,"🟢 Green",IF(L5>=0.75,"🟡 Yellow","🔴 Red"))) -> 🟢 Green | N5: =SUMIFS('VAM Team Sprint-CostperSprint'!I:I,'VAM Team Sprint-CostperSprint'!$A:$A,$A5) -> 84 | O5: =SUMIFS('VAM Team Sprint-CostperSprint'!H:H,'VAM Team Sprint-CostperSprint'!$A:$A,$A5) -> 4
A6: Sprint 2 | B6: February | C6: =SUMIFS('Team Sprints Input'!F:F,'Team Sprints Input'!$A:$A,$A6) -> 588 | D6: =SUMIFS('Team Sprints Input'!G:G,'Team Sprints Input'!$A:$A,$A6) -> 40 | E6: =SUMIFS('Team Sprints Input'!H:H,'Team Sprints Input'!$A:$A,$A6) -> 64 | F6: =SUMIFS('Team Sprints Input'!I:I,'Team Sprints Input'!$A:$A,$A6) -> 370 | G6: =SUMIFS('Team Sprints Input'!J:J,'Team Sprints Input'!$A:$A,$A6) -> 41 | H6: =SUMIFS('Team Sprints Input'!K:K,'Team Sprints Input'!$A:$A,$A6) -> 34 | I6: =C6+E6 -> 652 | J6: =F6+H6 -> 404 | K6: =SUMIFS('Team Sprints Input'!N:N, 'Team Sprints Input'!A:A, A6, 'Team Sprints Input'!E:E, B6) -> 316 | L6: =IFERROR(J6/K6,"") -> 1.278481 | M6: =IF(L6="","",IF(L6>=0.85,"🟢 Green",IF(L6>=0.75,"🟡 Yellow","🔴 Red"))) -> 🟢 Green | N6: =SUMIFS('VAM Team Sprint-CostperSprint'!I:I,'VAM Team Sprint-CostperSprint'!$A:$A,$A6) -> 178 | O6: =SUMIFS('VAM Team Sprint-CostperSprint'!H:H,'VAM Team Sprint-CostperSprint'!$A:$A,$A6) -> 22
A7: Sprint 3 | B7: February | C7: =SUMIFS('Team Sprints Input'!F:F,'Team Sprints Input'!$A:$A,$A7) -> 439 | D7: =SUMIFS('Team Sprints Input'!G:G,'Team Sprints Input'!$A:$A,$A7) -> 31 | E7: =SUMIFS('Team Sprints Input'!H:H,'Team Sprints Input'!$A:$A,$A7) -> 144 | F7: =SUMIFS('Team Sprints Input'!I:I,'Team Sprints Input'!$A:$A,$A7) -> 140 | G7: =SUMIFS('Team Sprints Input'!J:J,'Team Sprints Input'!$A:$A,$A7) -> 10 | H7: =SUMIFS('Team Sprints Input'!K:K,'Team Sprints Input'!$A:$A,$A7) -> 75 | I7: =C7+E7 -> 583 | J7: =F7+H7 -> 215 | K7: =SUMIFS('Team Sprints Input'!N:N, 'Team Sprints Input'!A:A, A7, 'Team Sprints Input'!E:E, B7) -> 316 | L7: =IFERROR(J7/K7,"") -> 0.68037975 | M7: =IF(L7="","",IF(L7>=0.85,"🟢 Green",IF(L7>=0.75,"🟡 Yellow","🔴 Red"))) -> 🔴 Red | N7: =SUMIFS('VAM Team Sprint-CostperSprint'!I:I,'VAM Team Sprint-CostperSprint'!$A:$A,$A7) -> 147 | O7: =SUMIFS('VAM Team Sprint-CostperSprint'!H:H,'VAM Team Sprint-CostperSprint'!$A:$A,$A7) -> 66
A8: Sprint 4 | B8: March | C8: =SUMIFS('Team Sprints Input'!F:F,'Team Sprints Input'!$A:$A,$A8) -> 605 | D8: =SUMIFS('Team Sprints Input'!G:G,'Team Sprints Input'!$A:$A,$A8) -> 17 | E8: =SUMIFS('Team Sprints Input'!H:H,'Team Sprints Input'!$A:$A,$A8) -> 158 | F8: =SUMIFS('Team Sprints Input'!I:I,'Team Sprints Input'!$A:$A,$A8) -> 312 | G8: =SUMIFS('Team Sprints Input'!J:J,'Team Sprints Input'!$A:$A,$A8) -> 43 | H8: =SUMIFS('Team Sprints Input'!K:K,'Team Sprints Input'!$A:$A,$A8) -> 127 | I8: =C8+E8 -> 763 | J8: =F8+H8 -> 439 | K8: =SUMIFS('Team Sprints Input'!N:N, 'Team Sprints Input'!A:A, A8, 'Team Sprints Input'!E:E, B8) -> 316 | L8: =IFERROR(J8/K8,"") -> 1.3892405 | M8: =IF(L8="","",IF(L8>=0.85,"🟢 Green",IF(L8>=0.75,"🟡 Yellow","🔴 Red"))) -> 🟢 Green | N8: =SUMIFS('VAM Team Sprint-CostperSprint'!I:I,'VAM Team Sprint-CostperSprint'!$A:$A,$A8) -> 323 | O8: =SUMIFS('VAM Team Sprint-CostperSprint'!H:H,'VAM Team Sprint-CostperSprint'!$A:$A,$A8) -> 108
A9: Sprint 5 | B9: March | C9: =SUMIFS('Team Sprints Input'!F:F,'Team Sprints Input'!$A:$A,$A9) -> 628 | D9: =SUMIFS('Team Sprints Input'!G:G,'Team Sprints Input'!$A:$A,$A9) -> 13 | E9: =SUMIFS('Team Sprints Input'!H:H,'Team Sprints Input'!$A:$A,$A9) -> 92 | F9: =SUMIFS('Team Sprints Input'!I:I,'Team Sprints Input'!$A:$A,$A9) -> 291 | G9: =SUMIFS('Team Sprints Input'!J:J,'Team Sprints Input'!$A:$A,$A9) -> 34 | H9: =SUMIFS('Team Sprints Input'!K:K,'Team Sprints Input'!$A:$A,$A9) -> 60 | I9: =C9+D9+E9 -> 733 | J9: =F9+H9 -> 351 | K9: =SUMIFS('Team Sprints Input'!N:N, 'Team Sprints Input'!A:A, A9, 'Team Sprints Input'!E:E, B9) -> 316 | L9: =IFERROR(J9/K9,"") -> 1.1107595 | M9: =IF(L9="","",IF(L9>=0.85,"🟢 Green",IF(L9>=0.75,"🟡 Yellow","🔴 Red"))) -> 🟢 Green | N9: =SUMIFS('VAM Team Sprint-CostperSprint'!I:I,'VAM Team Sprint-CostperSprint'!$A:$A,$A9) -> 164 | O9: =SUMIFS('VAM Team Sprint-CostperSprint'!H:H,'VAM Team Sprint-CostperSprint'!$A:$A,$A9) -> 37
A10: Sprint 6 | B10: March | C10: =SUMIFS('Team Sprints Input'!F:F,'Team Sprints Input'!$A:$A,$A10) -> 520 | D10: =SUMIFS('Team Sprints Input'!G:G,'Team Sprints Input'!$A:$A,$A10) -> 26 | E10: =SUMIFS('Team Sprints Input'!H:H,'Team Sprints Input'!$A:$A,$A10) -> 64 | F10: =SUMIFS('Team Sprints Input'!I:I,'Team Sprints Input'!$A:$A,$A10) -> 172 | G10: =SUMIFS('Team Sprints Input'!J:J,'Team Sprints Input'!$A:$A,$A10) -> 23 | H10: =SUMIFS('Team Sprints Input'!K:K,'Team Sprints Input'!$A:$A,$A10) -> 39 | I10: =C10+D10+E10 -> 610 | J10: =F10+H10 -> 211 | K10: =SUMIFS('Team Sprints Input'!N:N, 'Team Sprints Input'!A:A, A10, 'Team Sprints Input'!E:E, B10) -> 316 | L10: =IFERROR(J10/K10,"") -> 0.66772152 | M10: =IF(L10="","",IF(L10>=0.85,"🟢 Green",IF(L10>=0.75,"🟡 Yellow","🔴 Red"))) -> 🔴 Red | N10: =SUMIFS('VAM Team Sprint-CostperSprint'!I:I,'VAM Team Sprint-CostperSprint'!$A:$A,$A10) -> 113 | O10: =SUMIFS('VAM Team Sprint-CostperSprint'!H:H,'VAM Team Sprint-CostperSprint'!$A:$A,$A10) -> 20
A11: Q2 Sprint 1 | B11: April | C11: =SUMIFS('Team Sprints Input'!F:F,'Team Sprints Input'!$A:$A,$A11) -> 634 | D11: =SUMIFS('Team Sprints Input'!G:G,'Team Sprints Input'!$A:$A,$A11) -> 12 | E11: =SUMIFS('Team Sprints Input'!H:H,'Team Sprints Input'!$A:$A,$A11) -> 59 | F11: =SUMIFS('Team Sprints Input'!I:I,'Team Sprints Input'!$A:$A,$A11) -> 270 | G11: =SUMIFS('Team Sprints Input'!J:J,'Team Sprints Input'!$A:$A,$A11) -> 57 | H11: =SUMIFS('Team Sprints Input'!K:K,'Team Sprints Input'!$A:$A,$A11) -> 37 | I11: =C11+D11+E11 -> 705 | J11: =F11+H11 -> 307 | K11: =SUMIFS('Team Sprints Input'!N:N, 'Team Sprints Input'!A:A, A11, 'Team Sprints Input'!E:E, B11) -> 316 | L11: =IFERROR(J11/K11,"") -> 0.97151899 | M11: =IF(L11="","",IF(L11>=0.85,"🟢 Green",IF(L11>=0.75,"🟡 Yellow","🔴 Red"))) -> 🟢 Green | N11: =SUMIFS('VAM Team Sprint-CostperSprint'!I:I,'VAM Team Sprint-CostperSprint'!$A:$A,$A11) -> 220 | O11: =SUMIFS('VAM Team Sprint-CostperSprint'!H:H,'VAM Team Sprint-CostperSprint'!$A:$A,$A11) -> 22
A12: Q2 Sprint 2 | B12: April | C12: =SUMIFS('Team Sprints Input'!F:F,'Team Sprints Input'!$A:$A,$A12) -> 648 | D12: =SUMIFS('Team Sprints Input'!G:G,'Team Sprints Input'!$A:$A,$A12) -> 13 | E12: =SUMIFS('Team Sprints Input'!H:H,'Team Sprints Input'!$A:$A,$A12) -> 145 | F12: =SUMIFS('Team Sprints Input'!I:I,'Team Sprints Input'!$A:$A,$A12) -> 136 | G12: =SUMIFS('Team Sprints Input'!J:J,'Team Sprints Input'!$A:$A,$A12) -> 11 | H12: =SUMIFS('Team Sprints Input'!K:K,'Team Sprints Input'!$A:$A,$A12) -> 102 | I12: =C12+D12+E12 -> 806 | J12: =F12+H12 -> 238 | K12: =SUMIFS('Team Sprints Input'!N:N, 'Team Sprints Input'!A:A, A12, 'Team Sprints Input'!E:E, B12) -> 316 | L12: =IFERROR(J12/K12,"") -> 0.75316456 | M12: =IF(L12="","",IF(L12>=0.85,"🟢 Green",IF(L12>=0.75,"🟡 Yellow","🔴 Red"))) -> 🟡 Yellow | N12: =SUMIFS('VAM Team Sprint-CostperSprint'!I:I,'VAM Team Sprint-CostperSprint'!$A:$A,$A12) -> 141 | O12: =SUMIFS('VAM Team Sprint-CostperSprint'!H:H,'VAM Team Sprint-CostperSprint'!$A:$A,$A12) -> 57
A13: Q2 Sprint 3 | B13: May | C13: =SUMIFS('Team Sprints Input'!F:F,'Team Sprints Input'!$A:$A,$A13) -> 586 | D13: =SUMIFS('Team Sprints Input'!G:G,'Team Sprints Input'!$A:$A,$A13) -> 5 | E13: =SUMIFS('Team Sprints Input'!H:H,'Team Sprints Input'!$A:$A,$A13) -> 108 | F13: =SUMIFS('Team Sprints Input'!I:I,'Team Sprints Input'!$A:$A,$A13) -> 207 | G13: =SUMIFS('Team Sprints Input'!J:J,'Team Sprints Input'!$A:$A,$A13) -> 32 | H13: =SUMIFS('Team Sprints Input'!K:K,'Team Sprints Input'!$A:$A,$A13) -> 61 | I13: =C13+D13+E13 -> 699 | J13: =F13+G13+H13 -> 300 | K13: =SUMIFS('Team Sprints Input'!N:N, 'Team Sprints Input'!A:A, A13, 'Team Sprints Input'!E:E, B13) -> 140 | L13: =IFERROR(J13/I13,"") -> 0.42918455 | M13: =IF(L13="","",IF(L13>=0.85,"🟢 Green",IF(L13>=0.75,"🟡 Yellow","🔴 Red"))) -> 🔴 Red | N13: =SUMIFS('VAM Team Sprint-CostperSprint'!I:I,'VAM Team Sprint-CostperSprint'!$A:$A,$A13) -> 169 | O13: =SUMIFS('VAM Team Sprint-CostperSprint'!H:H,'VAM Team Sprint-CostperSprint'!$A:$A,$A13) -> 41
A14: Q2 Sprint 4 | B14: May | C14: =SUMIFS('Team Sprints Input'!F:F,'Team Sprints Input'!$A:$A,$A14) -> 485 | D14: =SUMIFS('Team Sprints Input'!G:G,'Team Sprints Input'!$A:$A,$A14) -> 11 | E14: =SUMIFS('Team Sprints Input'!H:H,'Team Sprints Input'!$A:$A,$A14) -> 128 | F14: =SUMIFS('Team Sprints Input'!I:I,'Team Sprints Input'!$A:$A,$A14) -> 147 | G14: =SUMIFS('Team Sprints Input'!J:J,'Team Sprints Input'!$A:$A,$A14) -> 20 | H14: =SUMIFS('Team Sprints Input'!K:K,'Team Sprints Input'!$A:$A,$A14) -> 90 | I14: =C14+D14+E14 -> 624 | J14: =F14+G14+H14 -> 257 | K14: =SUMIFS('Team Sprints Input'!N:N, 'Team Sprints Input'!A:A, A14, 'Team Sprints Input'!E:E, B14) -> 140 | L14: =IFERROR(J14/I14,"") -> 0.41185897 | M14: =IF(L14="","",IF(L14>=0.85,"🟢 Green",IF(L14>=0.75,"🟡 Yellow","🔴 Red"))) -> 🔴 Red | N14: =SUMIFS('VAM Team Sprint-CostperSprint'!I:I,'VAM Team Sprint-CostperSprint'!$A:$A,$A14) -> 162 | O14: =SUMIFS('VAM Team Sprint-CostperSprint'!H:H,'VAM Team Sprint-CostperSprint'!$A:$A,$A14) -> 48
A15: Q2 Sprint 5 | B15: June | C15: =SUMIFS('Team Sprints Input'!F:F,'Team Sprints Input'!$A:$A,$A15) -> 397 | D15: =SUMIFS('Team Sprints Input'!G:G,'Team Sprints Input'!$A:$A,$A15) -> 9 | E15: =SUMIFS('Team Sprints Input'!H:H,'Team Sprints Input'!$A:$A,$A15) -> 133 | F15: =SUMIFS('Team Sprints Input'!I:I,'Team Sprints Input'!$A:$A,$A15) -> 185 | G15: =SUMIFS('Team Sprints Input'!J:J,'Team Sprints Input'!$A:$A,$A15) -> 28 | H15: =SUMIFS('Team Sprints Input'!K:K,'Team Sprints Input'!$A:$A,$A15) -> 104 | I15: =C15+D15+E15 -> 539 | J15: =F15+G15+H15 -> 317 | K15: =SUMIFS('Team Sprints Input'!N:N, 'Team Sprints Input'!A:A, A15, 'Team Sprints Input'!E:E, B15) -> 140 | L15: =IFERROR(J15/I15,"") -> 0.58812616 | M15: =IF(L15="","",IF(L15>=0.85,"🟢 Green",IF(L15>=0.75,"🟡 Yellow","🔴 Red"))) -> 🔴 Red | N15: =SUMIFS('VAM Team Sprint-CostperSprint'!I:I,'VAM Team Sprint-CostperSprint'!$A:$A,$A15) -> 215 | O15: =SUMIFS('VAM Team Sprint-CostperSprint'!H:H,'VAM Team Sprint-CostperSprint'!$A:$A,$A15) -> 83
A16: Q2 Sprint 6 | B16: June | C16: =SUMIFS('Team Sprints Input'!F:F,'Team Sprints Input'!$A:$A,$A16) -> 401 | D16: =SUMIFS('Team Sprints Input'!G:G,'Team Sprints Input'!$A:$A,$A16) -> 1 | E16: =SUMIFS('Team Sprints Input'!H:H,'Team Sprints Input'!$A:$A,$A16) -> 144 | F16: =SUMIFS('Team Sprints Input'!I:I,'Team Sprints Input'!$A:$A,$A16) -> 122 | G16: =SUMIFS('Team Sprints Input'!J:J,'Team Sprints Input'!$A:$A,$A16) -> 7 | H16: =SUMIFS('Team Sprints Input'!K:K,'Team Sprints Input'!$A:$A,$A16) -> 73 | I16: =C16+D16+E16 -> 546 | J16: =F16+G16+H16 -> 202 | K16: =SUMIFS('Team Sprints Input'!N:N, 'Team Sprints Input'!A:A, A16, 'Team Sprints Input'!E:E, B16) -> 140 | L16: =IFERROR(J16/I16,"") -> 0.36996337 | M16: =IF(L16="","",IF(L16>=0.85,"🟢 Green",IF(L16>=0.75,"🟡 Yellow","🔴 Red"))) -> 🔴 Red | N16: =SUMIFS('VAM Team Sprint-CostperSprint'!I:I,'VAM Team Sprint-CostperSprint'!$A:$A,$A16) -> 135 | O16: =SUMIFS('VAM Team Sprint-CostperSprint'!H:H,'VAM Team Sprint-CostperSprint'!$A:$A,$A16) -> 50
A17: Sprint 7 | B17: August | J17: =IF(D17+E17+F17=0,"",D17+E17+F17) | L17: =IF(G17+H17+I17=0,"",G17+H17+I17) | M17: =IFERROR(L17/J17,"") | P17: =IF(M17="","",IF(M17>=0.85,"🟢 Green",IF(M17>=0.75,"🟡 Yellow","🔴 Red")))
A19: MONTHLY ROLLUP — Commitment Reliability (Stable, Improving and Declining) | G19: MONTHLY ROLLUP — Commitment Reliability (Stable, Improving and Declining)
A20: Month | B20: Sprints in Month | C20: Avg Completion % | D20: Monthly CR Status | E20: 3-Sprint Trend | G20: Month | H20: Sprints in Month | I20: Avg Completion % | J20: Monthly CR Status | K20: 3-Sprint Trend
A21: January | B21: =COUNTIF(B5:B17,A21) -> 1 | C21: =IFERROR(AVERAGEIF($B$5:$B$17,A21,$L$5:$L$17),"") -> 1 | D21: =IF(C21="","",IF(C21>=0.85,"🟢 Green",IF(C21>=0.75,"🟡 Yellow","🔴 Red"))) -> 🟢 Green | E21: =IF(COUNTA(C21:C21)<3,"(need 3mo)",IF(AVERAGE(C21:C21)>=0.85,"↑ Improving",IF(AVERAGE(C21:C21)>=0.75,"→ Stable","↓ Declining"))) -> (need 3mo) | G21: June | H21: =COUNTIF(B5:B20,G21) -> 2 | I21: =IFERROR(AVERAGEIF($B$5:$B$17,G21,$L$5:$L$17),"") -> 0.47904476 | J21: =IF(I21="","",IF(I21>=0.85,"🟢 Green",IF(I21>=0.75,"🟡 Yellow","🔴 Red"))) -> 🔴 Red | K21: =IF(COUNTA(C24:C25,I21)<3,"(need 3mo)",IF(AVERAGE(C24:C25,I21)>=0.85,"↑ Improving",IF(AVERAGE(C24:C25,I21)>=0.75,"→ Stable","↓ Declining"))) -> ↓ Declining
A22: February | B22: =COUNTIF(B6:B18,A22) -> 2 | C22: =IFERROR(AVERAGEIF($B$5:$B$17,A22,$L$5:$L$17),"") -> 0.97943038 | D22: =IF(C22="","",IF(C22>=0.85,"🟢 Green",IF(C22>=0.75,"🟡 Yellow","🔴 Red"))) -> 🟢 Green | E22: =IF(COUNTA(C21:C22)<3,"(need 3mo)",IF(AVERAGE(C21:C22)>=0.85,"↑ Improving",IF(AVERAGE(C21:C22)>=0.75,"→ Stable","↓ Declining"))) -> (need 3mo)
A23: March | B23: =COUNTIF(B7:B19,A23) -> 3 | C23: =IFERROR(AVERAGEIF($B$5:$B$17,A23,$L$5:$L$17),"") -> 1.0559072 | D23: =IF(C23="","",IF(C23>=0.85,"🟢 Green",IF(C23>=0.75,"🟡 Yellow","🔴 Red"))) -> 🟢 Green | E23: =IF(COUNTA(C21:C23)<3,"(need 3mo)",IF(AVERAGE(C21:C23)>=0.85,"↑ Improving",IF(AVERAGE(C21:C23)>=0.75,"→ Stable","↓ Declining"))) -> ↑ Improving
A24: April | B24: =COUNTIF(B8:B20,A24) -> 2 | C24: =IFERROR(AVERAGEIF($B$5:$B$17,A24,$L$5:$L$17),"") -> 0.86234177 | D24: =IF(C24="","",IF(C24>=0.85,"🟢 Green",IF(C24>=0.75,"🟡 Yellow","🔴 Red"))) -> 🟢 Green | E24: =IF(COUNTA(C22:C24)<3,"(need 3mo)",IF(AVERAGE(C22:C24)>=0.85,"↑ Improving",IF(AVERAGE(C22:C24)>=0.75,"→ Stable","↓ Declining"))) -> ↑ Improving
A25: May | B25: =COUNTIF(B9:B21,A25) -> 2 | C25: =IFERROR(AVERAGEIF($B$5:$B$17,A25,$L$5:$L$17),"") -> 0.42052176 | D25: =IF(C25="","",IF(C25>=0.85,"🟢 Green",IF(C25>=0.75,"🟡 Yellow","🔴 Red"))) -> 🔴 Red | E25: =IF(COUNTA(C23:C25)<3,"(need 3mo)",IF(AVERAGE(C23:C25)>=0.85,"↑ Improving",IF(AVERAGE(C23:C25)>=0.75,"→ Stable","↓ Declining"))) -> → Stable
A26: SECTION B — Cycle Time (Median) - Baseline=0% - Green; Baseline <=10% - Yellow; Baseline >10%- Red
A27: Cycle Time (Development → Testing → Review → Done) = Start Date → Done Date (days). Enter median for the sprint from JIRA
A28: Sprint ID | B28: Month | C28: Median Cycle Time (days) | D28: Baseline Cycle Time | E28: Δ vs Baseline | F28: Δ% vs Baseline | G28: CT Status
A30: Sprint 1 | B30: January | C30: =ROUND(AVERAGEIF('Team Median Input'!A:A, A30, 'Team Median Input'!J:J),1) -> 5.3 | D30: 5.4 | E30: =IFERROR(IF(C30="","",C30-D30),"") -> -0.1 | F30: =IFERROR(IF(C30="","",C30/D30-1),"") -> -0.018518519 | G30: =IF(F30="","",IF(F30<=0,"🟢 Green",IF(F30<=0.1,"🟡 Yellow","🔴 Red"))) -> 🟢 Green
A31: Sprint 2 | B31: February | C31: =AVERAGEIF('Team Median Input'!A:A, A31, 'Team Median Input'!J:J) -> 5.335 | D31: 5.4 | E31: =IFERROR(IF(C31="","",C31-D31),"") -> -0.065 | F31: =IFERROR(IF(C31="","",C31/D31-1),"") -> -0.012037037 | G31: =IF(F31="","",IF(F31<=0,"🟢 Green",IF(F31<=0.1,"🟡 Yellow","🔴 Red"))) -> 🟢 Green
A32: Sprint 3 | B32: February | C32: =AVERAGEIF('Team Median Input'!A:A, A32, 'Team Median Input'!J:J) -> 3.7225 | D32: 5.4 | E32: =IFERROR(IF(C32="","",C32-D32),"") -> -1.6775 | F32: =IFERROR(IF(C32="","",C32/D32-1),"") -> -0.31064815 | G32: =IF(F32="","",IF(F32<=0,"🟢 Green",IF(F32<=0.1,"🟡 Yellow","🔴 Red"))) -> 🟢 Green
A33: Sprint 4 | B33: March | C33: =AVERAGEIF('Team Median Input'!A:A, A33, 'Team Median Input'!J:J) -> 4.3325 | D33: 5.4 | E33: =IFERROR(IF(C33="","",C33-D33),"") -> -1.0675 | F33: =IFERROR(IF(C33="","",C33/D33-1),"") -> -0.19768519 | G33: =IF(F33="","",IF(F33<=0,"🟢 Green",IF(F33<=0.1,"🟡 Yellow","🔴 Red"))) -> 🟢 Green
A34: Sprint 5 | B34: March | C34: =AVERAGEIF('Team Median Input'!A:A, A34, 'Team Median Input'!J:J) -> 5.7075 | D34: 5.4 | E34: =IFERROR(IF(C34="","",C34-D34),"") -> 0.3075 | F34: =IFERROR(IF(C34="","",C34/D34-1),"") -> 0.056944444 | G34: =IF(F34="","",IF(F34<=0,"🟢 Green",IF(F34<=0.1,"🟡 Yellow","🔴 Red"))) -> 🟡 Yellow
A35: Sprint 6 | B35: March | C35: =AVERAGEIF('Team Median Input'!A:A, A35, 'Team Median Input'!J:J) -> 6.0325 | D35: 5.4 | E35: =IFERROR(IF(C35="","",C35-D35),"") -> 0.6325 | F35: =IFERROR(IF(C35="","",C35/D35-1),"") -> 0.11712963 | G35: =IF(F35="","",IF(F35<=0,"🟢 Green",IF(F35<=0.1,"🟡 Yellow","🔴 Red"))) -> 🔴 Red
A36: Q2 Sprint 1 | B36: April | C36: =AVERAGEIF('Team Median Input'!A:A, A36, 'Team Median Input'!J:J) -> 4.685 | D36: 5.4 | E36: =IFERROR(IF(C36="","",C36-D36),"") -> -0.715 | F36: =IFERROR(IF(C36="","",C36/D36-1),"") -> -0.13240741 | G36: =IF(F36="","",IF(F36<=0,"🟢 Green",IF(F36<=0.1,"🟡 Yellow","🔴 Red"))) -> 🟢 Green
A37: Q2 Sprint 2 | B37: April | C37: =AVERAGEIF('Team Median Input'!A:A, A37, 'Team Median Input'!J:J) -> 4.35 | D37: 5.4 | E37: =IFERROR(IF(C37="","",C37-D37),"") -> -1.05 | F37: =IFERROR(IF(C37="","",C37/D37-1),"") -> -0.19444444 | G37: =IF(F37="","",IF(F37<=0,"🟢 Green",IF(F37<=0.1,"🟡 Yellow","🔴 Red"))) -> 🟢 Green
A38: Q2 Sprint 3 | B38: May | C38: =AVERAGEIF('Team Median Input'!A:A, A38, 'Team Median Input'!J:J) -> 4.1666667 | D38: 5.4 | E38: =IFERROR(IF(C38="","",C38-D38),"") -> -1.2333333 | F38: =IFERROR(IF(C38="","",C38/D38-1),"") -> -0.22839506 | G38: =IF(F38="","",IF(F38<=0,"🟢 Green",IF(F38<=0.1,"🟡 Yellow","🔴 Red"))) -> 🟢 Green
A39: Q2 Sprint 4 | B39: May | C39: =AVERAGEIF('Team Median Input'!A:A, A39, 'Team Median Input'!J:J) -> 5.3025 | D39: 5.4 | E39: =IFERROR(IF(C39="","",C39-D39),"") -> -0.0975 | F39: =IFERROR(IF(C39="","",C39/D39-1),"") -> -0.018055556 | G39: =IF(F39="","",IF(F39<=0,"🟢 Green",IF(F39<=0.1,"🟡 Yellow","🔴 Red"))) -> 🟢 Green
A40: Q2 Sprint 5 | B40: June | C40: =AVERAGEIF('Team Median Input'!A:A, A40, 'Team Median Input'!J:J) -> 5.1 | D40: 5.4 | E40: =IFERROR(IF(C40="","",C40-D40),"") -> -0.3 | F40: =IFERROR(IF(C40="","",C40/D40-1),"") -> -0.055555556 | G40: =IF(F40="","",IF(F40<=0,"🟢 Green",IF(F40<=0.1,"🟡 Yellow","🔴 Red"))) -> 🟢 Green
A41: Q2 Sprint 6 | B41: June | C41: =AVERAGEIF('Team Median Input'!A:A, A41, 'Team Median Input'!J:J) -> 10.14 | D41: 5.4 | E41: =IFERROR(IF(C41="","",C41-D41),"") -> 4.74 | F41: =IFERROR(IF(C41="","",C41/D41-1),"") -> 0.87777778 | G41: =IF(F41="","",IF(F41<=0,"🟢 Green",IF(F41<=0.1,"🟡 Yellow","🔴 Red"))) -> 🔴 Red
E42: =IFERROR(IF(C42="","",C42-D42),"") | F42: =IFERROR(IF(C42="","",C42/D42-1),"") | G42: =IF(F42="","",IF(F42<=0,"🟢 Green",IF(F42<=0.1,"🟡 Yellow","🔴 Red")))
...

Sheet 📐 Formulas
B1: METRIC DEFINITIONS, FORMULAS & THRESHOLDS — Reference
B3: Metric | C3: Formula | D3: 🟡 Green | E3: 🟡 Yellow | F3: 🔴 Red | G3: Frequency / Notes
B4: EAC vs SOW Budget | C4: EAC ÷ SOW Budget Target × 100 | D4: ≤ 100% | E4: 100–105% | F4: > 105% | G4: Monthly. Top drivers required if Yellow/Red.
B5: Monthly Sprint Burn Variance | C5: (Actual Spend − Planned Spend) ÷ Planned Spend × 100 | D5: ≤ ±5% | E5: ±5–10% | F5: > ±10% | G5: Monthly. Log drivers: rework, delays, scope, staffing.
B6: Cost per Story Point — Story Points Delivered | C6: Team Cost ($) ÷ Story Points Delivered (Team SP only) | D6: Stable or ↓ vs baseline | E6: ↑ 5–10% vs baseline | F6: ↑ >10% vs baseline | G6: Monthly; rolling 3-month avg for trend. Baseline = first full sprint month.
B7: Cost per Story Point — Defects delivered | C7: Team Cost ($) ÷ Total SP (Team SP + Defect SP) | D7: Stable or ↓ vs baseline | E7: ↑ 5–10% vs baseline | F7: ↑ >10% vs baseline | G7: Monthly; defect work sized and included. Same baseline as Team.
B8: Commitment Reliability | C8: Total Completed (Stories+Defects+Bugs) ÷ Total Committed × 100 | D8: ≥ 85% | E8: 75–84% | F8: < 75% | G8: Per sprint + monthly rollup + 3-sprint trend.
B9: Cycle Time (Median) | C9: Median(Done Date − In-Progress) across all cards in period | D9: Stable or ↓ vs baseline | E9: ↑ up to 10% vs baseline | F9: ↑ > 10% vs baseline | G9: Per sprint + monthly rollup + 3-sprint trend. Start = first In Progress.
B10: Production Defect Leakage (Severity-Weighted) | C10: Total Prod Defects ÷ All Pre-Prod Defects × 100 | D10: ≤ 10% | E10: 11–15% | F10: > 15% | G10: Monthly + per release/feature. Measured post-deployment.
B11: Rework Ratio | C11: (Story and Standalone Bug Fix Effort ÷ Total Points Delivered) × 100 | D11: ≤ 20% | E11: 21–30% | F11: > 30% | G11: Monthly with rolling trend.
B12: First Time Pass Rate | C12: (Stories Completed w/o any defects ÷ Total stories delivered) × 100 | D12: ≥ 95% | E12: ≥ 85% | F12: < 85% | G12: Monthly with rolling trend.
B14: KEY ASSUMPTIONS & NOTES
B15: Baseline setting | C15: Set the Cost/SP and Cycle Time baselines ONCE in the yellow-highlighted cells on first use. These persist as the reference for all RAG calculations.
B16: Defect sizing | C16: Defects must be estimated in story points BEFORE the sprint to be included in Cost/SP program calculation and sprint commitment.
B17: Severity weighting | C17: Use weights in Quality sheet if we decide to use them for severity scales.
B18: Rework Effort | C18: Capture Story Defects and Standalone Bug Fix Points/counts ÷ Total Story Points in JIRA tool for accurate Rework Ratio.
B19: Cycle time source | C19: Pull median cycle time from JIRA (Control Charts). Exclude blocked time if used for any reason

Sheet Team Sprints Input
A1: Team Wise Sprint Input
A2: Sprint ID | B2: Team | C2: Sprint Start Date | D2: Sprint End Date | E2: Month | F2: Stories Planned | G2: Sprint Defects Planned | H2: Standalone Bugs Planned | I2: Stories Completed | J2: Story Defects Completed | K2: Standalone Bugs Completed | L2: Total Planned | M2: Total Completed | N2: Baseline Velocity | O2: Rework Ratio | P2: Comments
A3: Sprint 1 | B3: Team 1 | C3: 46029 | D3: 46042 | E3: January | F3: 0 | G3: 0 | H3: 0 | I3: 0 | J3: 0 | K3: 0 | L3: =F3+H3 -> 0 | M3: =I3+K3 -> 0 | O3: =SUM(J3:K3)/M3 -> #DIV/0!
A4: Sprint 1 | B4: Team 2 | C4: 46029 | D4: 46042 | E4: January | F4: 48 | G4: 13 | H4: 0 | I4: 30 | J4: 5 | K4: 0 | L4: =F4+H4 -> 48 | M4: =I4+K4 -> 30 | N4: 45 | O4: =K4/M4 -> 0 | P4: Lot of cards spilled over to pending testing and defects
A5: Sprint 1 | B5: Team 3 | C5: 46029 | D5: 46042 | E5: January | F5: 120 | G5: 8 | H5: 10 | I5: 34 | J5: 1 | K5: 4 | L5: =F5+H5 -> 130 | M5: =I5+K5 -> 38 | N5: 36 | O5: =K5/M5 -> 0.10526316 | P5: All testing pending cards due to CSEI-11111 defect .Net Update Status Types testing was blocked. Save Token for Org Blocked due to CoreSuite not available with the functionality. COA tiles cards testing was blocked due to Experience Team misconfigured files in .net
A6: Sprint 1 | B6: Team 4 | C6: 46029 | D6: 46042 | E6: January | F6: 82 | G6: 3 | H6: 0 | I6: 48 | J6: 2 | K6: 0 | L6: =F6+H6 -> 82 | M6: =I6+K6 -> 48 | N6: 35 | O6: =K6/M6 -> 0 | P6: Few are CIM related cards and few are reports which are still in analysis phase
A7: Sprint 2 | B7: Team 1 | C7: 46043 | D7: 46056 | E7: February | F7: 352 | G7: 33 | H7: 50 | I7: 260 | J7: 28 | K7: 26 | L7: =F7+H7 -> 402 | M7: =I7+K7 -> 286 | N7: 200 | O7: =K7/M7 -> 0.090909091
A8: Sprint 2 | B8: Team 2 | C8: 46043 | D8: 46056 | E8: February | F8: 63 | G8: 5 | H8: 2 | I8: 56 | J8: 9 | K8: 2 | L8: =F8+H8 -> 65 | M8: =I8+K8 -> 58 | N8: 45 | O8: =K8/M8 -> 0.034482759
A9: Sprint 2 | B9: Team 3 | C9: 46043 | D9: 46056 | E9: February | F9: 104 | G9: 2 | H9: 12 | I9: 36 | J9: 3 | K9: 6 | L9: =F9+H9 -> 116 | M9: =I9+K9 -> 42 | N9: 36 | O9: =K9/M9 -> 0.14285714 | P9: Due to CSEI-11111 defect .Net Update Status Types testing was blocked CSEI-10456 defect blocked few mendix cards for organization tokenid Payment Center .Net cards were blocked due to Policy Inquiry API schema mismatch for PreActive OneTime GuestPayment - New Work in Payment Centerweb, MDM - Policy Status issues identified at last moment
A10: Sprint 2 | B10: Team 4 | C10: 46043 | D10: 46056 | E10: February | F10: 69 | G10: 0 | H10: 0 | I10: 18 | J10: 1 | K10: 0 | L10: =F10+H10 -> 69 | M10: =I10+K10 -> 18 | N10: 35 | O10: =K10/M10 -> 0 | P10: Spill over mostly data suit reports
A11: Sprint 3 | B11: Team 1 | C11: 46057 | D11: 46070 | E11: February | F11: =319-113 -> 206 | G11: 20 | H11: =61+52 -> 113 | I11: =105-52 -> 53 | J11: 2 | K11: 52 | L11: =F11+H11 -> 319 | M11: =I11+K11 -> 105 | N11: 200 | O11: =K11/M11 -> 0.4952381
A12: Sprint 3 | B12: Team 2 | C12: 46057 | D12: 46070 | E12: February | F12: 61 | G12: 7 | H12: 4 | I12: 35 | J12: 8 | K12: 4 | L12: =F12+H12 -> 65 | M12: =I12+K12 -> 39 | N12: 45 | O12: =K12/M12 -> 0.1025641 | P12: Due to testing spillover and review pending
A13: Sprint 3 | B13: Team 3 | C13: 46057 | D13: 46070 | E13: February | F13: 83 | G13: 0 | H13: 26 | I13: 16 | J13: 0 | K13: 18 | L13: =F13+H13 -> 109 | M13: =I13+K13 -> 34 | N13: 36 | O13: =K13/M13 -> 0.52941176 | P13: Due to CSEI-11111 defect .Net Update Status Types testing was blocked.
A14: Sprint 3 | B14: Team 4 | C14: 46057 | D14: 46070 | E14: February | F14: =53+36 -> 89 | G14: 4 | H14: 1 | I14: 36 | J14: 0 | K14: 1 | L14: =F14+H14 -> 90 | M14: =I14+K14 -> 37 | N14: 35 | O14: =K14/M14 -> 0.027027027
A15: Sprint 4 | B15: Team 1 | C15: 46071 | D15: 46084 | E15: March | F15: =454-132 -> 322 | G15: 2 | H15: =28+104 -> 132 | I15: =246-104 -> 142 | J15: 19 | K15: 104 | L15: =F15+H15 -> 454 | M15: =I15+K15 -> 246 | N15: 200 | O15: =K15/M15 -> 0.42276423
A16: Sprint 4 | B16: Team 2 | C16: 46071 | D16: 46084 | E16: March | F16: 80 | G16: 11 | H16: 7 | I16: 69 | J16: 13 | K16: 7 | L16: =F16+H16 -> 87 | M16: =I16+K16 -> 76 | N16: 45 | O16: =K16/M16 -> 0.092105263
A17: Sprint 4 | B17: Team 3 | C17: 46071 | D17: 46084 | E17: March | F17: 91 | G17: 3 | H17: 17 | I17: 56 | J17: 6 | K17: 14 | L17: =F17+H17 -> 108 | M17: =I17+K17 -> 70 | N17: 36 | O17: =K17/M17 -> 0.2 | P17: Integration cards were spilled due to dependency on CSEI-7531. still not delivered Bene related mendix cards are spilled due to integration card dependency which are planned in SP5
A18: Sprint 4 | B18: Team 4 | C18: 46071 | D18: 46084 | E18: March | F18: =67+45 -> 112 | G18: 1 | H18: 2 | I18: 45 | J18: 5 | K18: 2 | L18: =F18+H18 -> 114 | M18: =I18+K18 -> 47 | N18: 35 | O18: =K18/M18 -> 0.042553191 | P18: Data suite Report cards and cards related for Fund file are spilled over due to pending requirement
A19: Sprint 5 | B19: Team 1 | C19: 46085 | D19: 46098 | E19: March | F19: 369 | G19: 3 | H19: 62 | I19: 194 | J19: 25 | K19: 43 | L19: =F19+H19 -> 431 | M19: =I19+K19 -> 237 | N19: 200 | O19: =K19/M19 -> 0.1814346
A20: Sprint 5 | B20: Team 2 | C20: 46085 | D20: 46098 | E20: March | F20: 75 | G20: 8 | H20: 9 | I20: 39 | J20: 4 | K20: 9 | L20: =F20+H20 -> 84 | M20: =I20+K20 -> 48 | N20: 45 | O20: =K20/M20 -> 0.1875
A21: Sprint 5 | B21: Team 3 | C21: 46085 | D21: 46098 | E21: March | F21: 91 | G21: 1 | H21: 21 | I21: 28 | J21: 1 | K21: 8 | L21: =F21+H21 -> 112 | M21: =I21+K21 -> 36 | N21: 36 | O21: =K21/M21 -> 0.22222222
A22: Sprint 5 | B22: Team 4 | C22: 46085 | D22: 46098 | E22: March | F22: 93 | G22: 1 | H22: 0 | I22: 30 | J22: 4 | K22: 0 | L22: =F22+H22 -> 93 | M22: =I22+K22 -> 30 | N22: 35 | O22: =K22/M22 -> 0
A23: Sprint 6 | B23: Team 1 | C23: 46099 | D23: 46112 | E23: March | F23: 281 | G23: 19 | H23: 43 | I23: 73 | J23: 11 | K23: 25 | L23: =F23+H23 -> 324 | M23: =I23+K23 -> 98 | N23: 200 | O23: =K23/M23 -> 0.25510204 | P23: BRP for multiple days. Reinstatement and conversion which are less priority cards are spilled over.
A24: Sprint 6 | B24: Team 2 | C24: 46099 | D24: 46112 | E24: March | F24: 93 | G24: 7 | H24: 3 | I24: 49 | J24: 7 | K24: 2 | L24: =F24+H24 -> 96 | M24: =I24+K24 -> 51 | N24: 45 | O24: =K24/M24 -> 0.039215686 | P24: Cards are spilled over due to Status not getting updated
A25: Sprint 6 | B25: Team 3 | C25: 46099 | D25: 46112 | E25: March | F25: 68 | G25: 0 | H25: 18 | I25: 13 | J25: 4 | K25: 12 | L25: =F25+H25 -> 86 | M25: =I25+K25 -> 25 | N25: 36 | O25: =K25/M25 -> 0.48 | P25: BRP was there for 2 days. Team had tempus issues multiple times so 3 defects belong to it. Status cards are blocked due to CoreSuite issues. Token ID, RNID company cards defects are fixed at the end of the sprint by Team 1.
A26: Sprint 6 | B26: Team 4 | C26: 46099 | D26: 46112 | E26: March | F26: 78 | G26: 0 | H26: 0 | I26: 37 | J26: 1 | K26: 0 | L26: =F26+H26 -> 78 | M26: =I26+K26 -> 37 | N26: 35 | O26: =K26/M26 -> 0
A27: Q2 Sprint 1 | B27: Team 1 | C27: 46113 | D27: 46126 | E27: April | F27: 308 | G27: 8 | H27: 38 | I27: 115 | J27: 45 | K27: 26 | L27: =F27+H27 -> 346 | M27: =I27+K27 -> 141 | N27: 200 | O27: =K27/M27 -> 0.18439716
A28: Q2 Sprint 1 | B28: Team 2 | C28: 46113 | D28: 46126 | E28: April | F28: 116 | G28: 4 | H28: 2 | I28: 52 | J28: 11 | K28: 2 | L28: =F28+H28 -> 118 | M28: =I28+K28 -> 54 | N28: 45 | O28: =K28/M28 -> 0.037037037
